<?xml version="1.0" encoding="utf-8"?>
<!-- This URDF was automatically created by SolidWorks to URDF Exporter! Originally created by Stephen Brawner (brawner@gmail.com) 
     Commit Version: 1.5.1-0-g916b5db  Build Version: 1.5.7152.31018
     For more information, please see http://wiki.ros.org/sw_urdf_exporter -->
<robot
  name="Robor">
  <link
    name="Chassis">
    <inertial>
      <origin
        xyz="0.034596 -0.5878 0.17916"
        rpy="0 0 0" />
      <mass
        value="10.436" />
      <inertia
        ixx="0.13134"
        ixy="2.3949E-06"
        ixz="-0.00076683"
        iyy="0.24927"
        iyz="9.4271E-09"
        izz="0.13119" />
    </inertial>
    <visual>
      <origin
        xyz="0 0 0"
        rpy="0 0 0" />
      <geometry>
        <mesh
          filename="package://Robor/meshes/Chassis.STL" />
      </geometry>
      <material
        name="">
        <color
          rgba="0.52941 0.54902 0.54902 1" />
      </material>
    </visual>
    <collision>
      <origin
        xyz="0 0 0"
        rpy="0 0 0" />
      <geometry>
        <mesh
          filename="package://Robor/meshes/Chassis.STL" />
      </geometry>
    </collision>
  </link>
  <link
    name="Right Wheel">
    <inertial>
      <origin
        xyz="-5.5511E-17 0.024462 2.237E-05"
        rpy="0 0 0" />
      <mass
        value="0.72827" />
      <inertia
        ixx="0.0013062"
        ixy="1.751E-20"
        ixz="-1.0842E-19"
        iyy="0.0023567"
        iyz="2.039E-07"
        izz="0.0013064" />
    </inertial>
    <visual>
      <origin
        xyz="0 0 0"
        rpy="0 0 0" />
      <geometry>
        <mesh
          filename="package://Robor/meshes/Right Wheel.STL" />
      </geometry>
      <material
        name="">
        <color
          rgba="0.79216 0.81961 0.93333 1" />
      </material>
    </visual>
    <collision>
      <origin
        xyz="0 0 0"
        rpy="0 0 0" />
      <geometry>
        <mesh
          filename="package://Robor/meshes/Right Wheel.STL" />
      </geometry>
    </collision>
  </link>
  <joint
    name="RW"
    type="continuous">
    <origin
      xyz="0.11841 -0.39765 0"
      rpy="-1.5708 0 0.78245" />
    <parent
      link="Chassis" />
    <child
      link="Right Wheel" />
    <axis
      xyz="0 1 0" />
    <limit
      lower="0"
      upper="0"
      effort="0"
      velocity="0" />
    <dynamics
      damping="1"
      friction="0.01" />
  </joint>
  <link
    name="Left Wheel">
    <inertial>
      <origin
        xyz="-5.5511E-17 0.025016 2.237E-05"
        rpy="0 0 0" />
      <mass
        value="0.72827" />
      <inertia
        ixx="0.0013062"
        ixy="-1.6292E-20"
        ixz="-1.6263E-19"
        iyy="0.0023567"
        iyz="2.039E-07"
        izz="0.0013064" />
    </inertial>
    <visual>
      <origin
        xyz="0 0 0"
        rpy="0 0 0" />
      <geometry>
        <mesh
          filename="package://Robor/meshes/Left Wheel.STL" />
      </geometry>
      <material
        name="">
        <color
          rgba="0.79216 0.81961 0.93333 1" />
      </material>
    </visual>
    <collision>
      <origin
        xyz="0 0 0"
        rpy="0 0 0" />
      <geometry>
        <mesh
          filename="package://Robor/meshes/Left Wheel.STL" />
      </geometry>
    </collision>
  </link>
  <joint
    name="LW"
    type="continuous">
    <origin
      xyz="0.11841 -0.39765 0.35775"
      rpy="1.5708 0 2.7649" />
    <parent
      link="Chassis" />
    <child
      link="Left Wheel" />
    <axis
      xyz="0 1 0" />
    <limit
      lower="0"
      upper="0"
      effort="0"
      velocity="0" />
    <dynamics
      damping="1"
      friction="0.01" />
  </joint>
  <link
    name="Castor Wheel">
    <inertial>
      <origin
        xyz="0 0 0"
        rpy="0 0 0" />
      <mass
        value="0.5" />
      <inertia
        ixx="0"
        ixy="0"
        ixz="0"
        iyy="0"
        iyz="0"
        izz="0" />
    </inertial>
    <visual>
      <origin
        xyz="0 0 0"
        rpy="0 0 0" />
      <geometry>
        <mesh
          filename="package://Robor/meshes/Castor Wheel.STL" />
      </geometry>
      <material
        name="">
        <color
          rgba="1 1 1 1" />
      </material>
    </visual>
    <collision>
      <origin
        xyz="0 0 0"
        rpy="0 0 0" />
      <geometry>
        <mesh
          filename="package://Robor/meshes/Castor Wheel.STL" />
      </geometry>
    </collision>
  </link>
  <joint
    name="CW"
    type="continuous">
    <origin
      xyz="-0.15394 -0.35895 0.2043"
      rpy="-1.5735 0.069867 -0.03916" />
    <parent
      link="Chassis" />
    <child
      link="Castor Wheel" />
    <axis
      xyz="0 1 0" />
    <limit
      lower="0"
      upper="0"
      effort="0"
      velocity="0" />
    <dynamics
      damping="1"
      friction="0.01" />
  </joint>
</robot>
