<sdf version='1.6'>
  <model name='Robor'>
    <link name='Chassis'>
      <pose frame=''>0 0 0 0 -0 0</pose>
      <inertial>
        <pose frame=''>0.034596 -0.5878 0.17916 0 -0 0</pose>
        <mass>10.436</mass>
        <inertia>
          <ixx>0.1</ixx>
          <ixy>0</ixy>
          <ixz>0</ixz>
          <iyy>0.1</iyy>
          <iyz>0</iyz>
          <izz>0.1</izz>
        </inertia>
      </inertial>
      <collision name='Chassis_collision'>
        <pose frame=''>0 0 0 0 -0 0</pose>
        <geometry>
          <mesh>
            <scale>1 1 1</scale>
            <uri>model://Robor/meshes/Chassis.STL</uri>
          </mesh>
        </geometry>
      </collision>
      <visual name='Chassis_visual'>
        <pose frame=''>0 0 0 0 -0 0</pose>
        <geometry>
          <mesh>
            <scale>1 1 1</scale>
            <uri>model://Robor/meshes/Chassis.STL</uri>
          </mesh>
        </geometry>
      </visual>
    </link>
    <link name='Castor Frame'>
      <pose frame=''>-0.13379 -0.42645 0.17915 1.5708 -0 0</pose>
      <inertial>
        <pose frame=''>-0.006153 4e-06 -0.025758 0 -0 0</pose>
        <mass>0.12593</mass>
        <inertia>
          <ixx>0.1</ixx>
          <ixy>0</ixy>
          <ixz>0</ixz>
          <iyy>0.1</iyy>
          <iyz>0</iyz>
          <izz>0.1</izz>
        </inertia>
      </inertial>
      <collision name='Castor Frame_collision'>
        <pose frame=''>0 0 0 0 -0 0</pose>
        <geometry>
          <mesh>
            <scale>1 1 1</scale>
            <uri>model://Robor/meshes/Castor Frame.STL</uri>
          </mesh>
        </geometry>
      </collision>
      <visual name='Castor Frame_visual'>
        <pose frame=''>0 0 0 0 -0 0</pose>
        <geometry>
          <mesh>
            <scale>1 1 1</scale>
            <uri>model://Robor/meshes/Castor Frame.STL</uri>
          </mesh>
        </geometry>
      </visual>
    </link>
    <joint name='CWF' type='revolute'>
      <child>Castor Frame</child>
      <parent>Chassis</parent>
      <axis>
        <xyz>0 -1 -4e-06</xyz>
        <limit>
          <lower>0</lower>
          <upper>0</upper>
          <effort>0</effort>
          <velocity>0</velocity>
        </limit>
        <dynamics>
          <spring_reference>0</spring_reference>
          <spring_stiffness>0</spring_stiffness>
        </dynamics>
        <use_parent_model_frame>1</use_parent_model_frame>
      </axis>
    </joint>
    <link name='Castor Wheel'>
      <pose frame=''>-0.169474 -0.360945 0.203906 1.5708 0.10274 0</pose>
      <inertial>
        <pose frame=''>0.016283 -0.023214 -0.001995 0 -0 0</pose>
        <mass>0.18068</mass>
        <inertia>
          <ixx>0.1</ixx>
          <ixy>0</ixy>
          <ixz>0</ixz>
          <iyy>0.1</iyy>
          <iyz>0</iyz>
          <izz>0.1</izz>
        </inertia>
      </inertial>
      <collision name='Castor Wheel_collision'>
        <pose frame=''>0 0 0 0 -0 0</pose>
        <geometry>
          <mesh>
            <scale>1 1 1</scale>
            <uri>model://Robor/meshes/Castor Wheel.STL</uri>
          </mesh>
        </geometry>
      </collision>
      <visual name='Castor Wheel_visual'>
        <pose frame=''>0 0 0 0 -0 0</pose>
        <geometry>
          <mesh>
            <scale>1 1 1</scale>
            <uri>model://Robor/meshes/Castor Wheel.STL</uri>
          </mesh>
        </geometry>
      </visual>
    </link>
    <joint name='CWW' type='revolute'>
      <child>Castor Wheel</child>
      <parent>Castor Frame</parent>
      <axis>
        <xyz>0 4e-06 -1</xyz>
        <limit>
          <lower>-1e+16</lower>
          <upper>1e+16</upper>
        </limit>
        <dynamics>
          <spring_reference>0</spring_reference>
          <spring_stiffness>0</spring_stiffness>
        </dynamics>
        <use_parent_model_frame>1</use_parent_model_frame>
      </axis>
    </joint>
    <link name='Left Wheel'>
      <pose frame=''>0.11841 -0.39765 0.35775 1.5708 -0 -0.37673</pose>
      <inertial>
        <pose frame=''>-1.5e-05 0.025016 1.7e-05 0 -0 0</pose>
        <mass>0.72827</mass>
        <inertia>
          <ixx>0.1</ixx>
          <ixy>0</ixy>
          <ixz>0</ixz>
          <iyy>0.1</iyy>
          <iyz>0</iyz>
          <izz>0.1</izz>
        </inertia>
      </inertial>
      <collision name='Left Wheel_collision'>
        <pose frame=''>0 0 0 0 -0 0</pose>
        <geometry>
          <mesh>
            <scale>1 1 1</scale>
            <uri>model://Robor/meshes/Left Wheel.STL</uri>
          </mesh>
        </geometry>
      </collision>
      <visual name='Left Wheel_visual'>
        <pose frame=''>0 0 0 0 -0 0</pose>
        <geometry>
          <mesh>
            <scale>1 1 1</scale>
            <uri>model://Robor/meshes/Left Wheel.STL</uri>
          </mesh>
        </geometry>
      </visual>
    </link>
    <joint name='LW' type='revolute'>
      <child>Left Wheel</child>
      <parent>Chassis</parent>
      <axis>
        <xyz>-1e-06 -3e-06 1</xyz>
        <limit>
          <lower>-1e+16</lower>
          <upper>1e+16</upper>
        </limit>
        <dynamics>
          <damping>1</damping>
          <friction>0.01</friction>
          <spring_reference>0</spring_reference>
          <spring_stiffness>0</spring_stiffness>
        </dynamics>
        <use_parent_model_frame>1</use_parent_model_frame>
      </axis>
    </joint>
    <link name='Right Wheel'>
      <pose frame=''>0.11841 -0.39765 0 -1.5708 -0 0.78245</pose>
      <inertial>
        <pose frame=''>2.2e-05 0.024462 3e-06 0 -0 0</pose>
        <mass>0.72827</mass>
        <inertia>
          <ixx>0.1</ixx>
          <ixy>0</ixy>
          <ixz>0</ixz>
          <iyy>0.1</iyy>
          <iyz>0</iyz>
          <izz>0.1</izz>
        </inertia>
      </inertial>
      <collision name='Right Wheel_collision'>
        <pose frame=''>0 0 0 0 -0 0</pose>
        <geometry>
          <mesh>
            <scale>1 1 1</scale>
            <uri>model://Robor/meshes/Right Wheel.STL</uri>
          </mesh>
        </geometry>
      </collision>
      <visual name='Right Wheel_visual'>
        <pose frame=''>0 0 0 0 -0 0</pose>
        <geometry>
          <mesh>
            <scale>1 1 1</scale>
            <uri>model://Robor/meshes/Right Wheel.STL</uri>
          </mesh>
        </geometry>
      </visual>
    </link>
    <joint name='RW' type='revolute'>
      <child>Right Wheel</child>
      <parent>Chassis</parent>
      <axis>
        <xyz>-3e-06 3e-06 1</xyz>
        <limit>
          <lower>-1e+16</lower>
          <upper>1e+16</upper>
        </limit>
        <dynamics>
          <damping>1</damping>
          <friction>0.01</friction>
          <spring_reference>0</spring_reference>
          <spring_stiffness>0</spring_stiffness>
        </dynamics>
        <use_parent_model_frame>1</use_parent_model_frame>
      </axis>
    </joint>
    <static>0</static>
    <plugin name='differential_drive_controller' filename='libgazebo_ros_diff_drive.so'>
      <legacyMode>0</legacyMode>
      <alwaysOn>1</alwaysOn>
      <updateRate>10</updateRate>
      <leftJoint>LW</leftJoint>
      <rightJoint>RW</rightJoint>
      <wheelSeparation>0.407</wheelSeparation>
      <wheelDiameter>0.153</wheelDiameter>
      <torque>10</torque>
      <commandTopic>cmd_vel</commandTopic>
      <odometryTopic>odom</odometryTopic>
      <odometryFrame>odom</odometryFrame>
      <robotBaseFrame>Chassis</robotBaseFrame>
      <publishWheelTF>0</publishWheelTF>
      <publishWheelJointState>0</publishWheelJointState>
      <rosDebugLevel>na</rosDebugLevel>
      <wheelAcceleration>0</wheelAcceleration>
      <wheelTorque>5</wheelTorque>
      <odometrySource>world</odometrySource>
      <publishTf>1</publishTf>
      <publishOdomTF>1</publishOdomTF>
    </plugin>
  </model>
</sdf>
