<sdf version='1.6'>
  <model name='Robor'>
    <link name='Chassis'>
      <pose frame=''>0 0 0 0 -0 0</pose>
      <inertial>
        <pose frame=''>0.029351 -0.581757 0.179182 0 -0 0</pose>
        <mass>10.7426</mass>
        <inertia>
          <ixx>0.144845</ixx>
          <ixy>0.0115947</ixy>
          <ixz>-0.000721381</ixz>
          <iyy>0.259509</iyy>
          <iyz>-4.96766e-05</iyz>
          <izz>0.1548</izz>
        </inertia>
      </inertial>
      <collision name='Chassis_collision'>
        <pose frame=''>0 0 0 0 -0 0</pose>
        <geometry>
          <mesh>
            <scale>1 1 1</scale>
            <uri>model://Robor/meshes/Chassis.STL</uri>
          </mesh>
        </geometry>
      </collision>
      <collision name='Chassis_fixed_joint_lump__Castor Wheel_collision_1'>
        <pose frame=''>-0.16947 -0.36094 0.20391 1.5708 0.10274 0</pose>
        <geometry>
          <mesh>
            <scale>1 1 1</scale>
            <uri>model://Robor/meshes/Castor Wheel.STL</uri>
          </mesh>
        </geometry>
      </collision>
      <visual name='Chassis_visual'>
        <pose frame=''>0 0 0 0 -0 0</pose>
        <geometry>
          <mesh>
            <scale>1 1 1</scale>
            <uri>model://Robor/meshes/Chassis.STL</uri>
          </mesh>
        </geometry>
      </visual>
      <visual name='Chassis_fixed_joint_lump__Castor Wheel_visual_1'>
        <pose frame=''>-0.16947 -0.36094 0.20391 1.5708 0.10274 0</pose>
        <geometry>
          <mesh>
            <scale>1 1 1</scale>
            <uri>model://Robor/meshes/Castor Wheel.STL</uri>
          </mesh>
        </geometry>
      </visual>
    </link>
    <link name='Left Wheel'>
      <pose frame=''>0.11841 -0.39765 0.35775 1.5708 -0 2.7649</pose>
      <inertial>
        <pose frame=''>1.5e-05 0.025016 -1.7e-05 0 -0 0</pose>
        <mass>0.72827</mass>
        <inertia>
          <ixx>0.0013063</ixx>
          <ixy>1.3321e-07</ixy>
          <ixz>-1.3543e-07</ixz>
          <iyy>0.0023567</iyy>
          <iyz>-1.5438e-07</iyz>
          <izz>0.0013063</izz>
        </inertia>
      </inertial>
      <collision name='Left Wheel_collision'>
        <pose frame=''>0 0 0 0 -0 0</pose>
        <geometry>
          <mesh>
            <scale>1 1 1</scale>
            <uri>model://Robor/meshes/Left Wheel.STL</uri>
          </mesh>
        </geometry>
      </collision>
      <visual name='Left Wheel_visual'>
        <pose frame=''>0 0 0 0 -0 0</pose>
        <geometry>
          <mesh>
            <scale>1 1 1</scale>
            <uri>model://Robor/meshes/Left Wheel.STL</uri>
          </mesh>
        </geometry>
      </visual>
    </link>
    <joint name='LW' type='revolute'>
      <child>Left Wheel</child>
      <parent>Chassis</parent>
      <axis>
        <xyz>1e-06 3e-06 1</xyz>
        <limit>
          <lower>-1e+16</lower>
          <upper>1e+16</upper>
        </limit>
        <dynamics>
          <damping>1</damping>
          <friction>0.01</friction>
          <spring_reference>0</spring_reference>
          <spring_stiffness>0</spring_stiffness>
        </dynamics>
        <use_parent_model_frame>1</use_parent_model_frame>
      </axis>
    </joint>
    <link name='Right Wheel'>
      <pose frame=''>0.11841 -0.39765 0 -1.5708 -0 0.78245</pose>
      <inertial>
        <pose frame=''>-0 0.024462 2.2e-05 0 -0 0</pose>
        <mass>0.72827</mass>
        <inertia>
          <ixx>0.0013062</ixx>
          <ixy>2.5001e-20</ixy>
          <ixz>0</ixz>
          <iyy>0.0023567</iyy>
          <iyz>2.039e-07</iyz>
          <izz>0.0013064</izz>
        </inertia>
      </inertial>
      <collision name='Right Wheel_collision'>
        <pose frame=''>0 0 0 0 -0 0</pose>
        <geometry>
          <mesh>
            <scale>1 1 1</scale>
            <uri>model://Robor/meshes/Right Wheel.STL</uri>
          </mesh>
        </geometry>
      </collision>
      <visual name='Right Wheel_visual'>
        <pose frame=''>0 0 0 0 -0 0</pose>
        <geometry>
          <mesh>
            <scale>1 1 1</scale>
            <uri>model://Robor/meshes/Right Wheel.STL</uri>
          </mesh>
        </geometry>
      </visual>
    </link>
    <joint name='RW' type='revolute'>
      <child>Right Wheel</child>
      <parent>Chassis</parent>
      <axis>
        <xyz>3e-06 -3e-06 -1</xyz>
        <limit>
          <lower>-1e+16</lower>
          <upper>1e+16</upper>
        </limit>
        <dynamics>
          <damping>1</damping>
          <friction>0.01</friction>
          <spring_reference>0</spring_reference>
          <spring_stiffness>0</spring_stiffness>
        </dynamics>
        <use_parent_model_frame>1</use_parent_model_frame>
      </axis>
    </joint>
    <static>0</static>
    <plugin name='differential_drive_controller' filename='libdiffdrive_plugin.so'>
      <rosDebugLevel>Debug</rosDebugLevel>
      <publishWheelTF>0</publishWheelTF>
      <robotNamespace>/</robotNamespace>
      <publishTf>1</publishTf>
      <publishWheelJointState>0</publishWheelJointState>
      <alwaysOn>1</alwaysOn>
      <updateRate>100.0</updateRate>
      <leftJoint>LW</leftJoint>
      <rightJoint>RW</rightJoint>
      <wheelSeparation>0.407</wheelSeparation>
      <wheelDiameter>0.153</wheelDiameter>
      <broadcastTF>1</broadcastTF>
      <wheelTorque>30</wheelTorque>
      <wheelAcceleration>0.0</wheelAcceleration>
      <commandTopic>cmd_vel</commandTopic>
      <odometryFrame>odom</odometryFrame>
      <odometryTopic>odom</odometryTopic>
      <robotBaseFrame>Chassis</robotBaseFrame>
    </plugin>
  </model>
</sdf>
